<?xml version="1.0"?>

<!-- Added the end effector casing as well as the Suction Gripper-->
<robot name="sr_scara_hx" xmlns:xacro="http://www.ros.org/wiki/xacro">

<xacro:property name="mass" value="1.000" /> 	  <!-- arbitrary value for mass -->
<xacro:property name="pos0" value="0.00158925" /> <!-- Link 1 -->
<xacro:property name="pos2" value="0.300" />      <!-- Link 2 -->
<xacro:property name="pos3" value="0" />          <!-- Link 3 -->


<!-- Import all Gazebo-customization elements, including Gazebo colors -->
<xacro:include filename="$(find robot_simulation)/URDF/sr_scara_hx.gazebo" />
<!-- Import Rviz colors -->
<xacro:include filename="$(find robot_simulation)/URDF/materials.xacro" />

<!--Links -->
<link name="base_link">
 <visual>
  <origin xyz="0 0 0.00158925" rpy="0 0 0" />
   <geometry>
     <mesh filename="package://robot_simulation/meshes/base_R01.stl" scale="0.001 0.001 0.001"/>  
   </geometry>
   <material name="black"/>
 </visual>
 <collision>
  <origin xyz="0 0 0.00158925" rpy="0 0 0" />
   <geometry>
     <mesh filename="package://robot_simulation/meshes/base_R01.stl" scale="0.001 0.001 0.001"/>  
   </geometry>
 </collision>  
 <inertial>
      <origin xyz="0 0 0.00158925" rpy="0 0 0"/>
      <mass value="30.0"/>
      <inertia
	  ixx="1.0" ixy="0.0" ixz="0.0"
	  iyy="1.0" iyz="0.0"
	  izz="1.0"/>
 </inertial>
</link>

<link name="link1">
 <visual>
  <origin xyz="0 0 0" rpy="0 0 0" />
   <geometry>
     <mesh filename="package://robot_simulation/meshes/arm_link_R01.stl" scale="0.001 0.001 0.001"/>  
   </geometry>
   <material name="red"/>
 </visual>
 <collision>
  <origin xyz="0 0 0" rpy="0 0 0" />
   <geometry>
     <mesh filename="package://robot_simulation/meshes/arm_link_R01.stl" scale="0.001 0.001 0.001"/>  
   </geometry>
 </collision>
 <inertial>
      <origin xyz="0 0 0" rpy="0 0 0"/>
      <mass value="10.0"/>
      <inertia
	  ixx="1.0" ixy="0.0" ixz="0.0"
	  iyy="1.0" iyz="0.0"
	  izz="1.0"/>
 </inertial>
</link>

<link name="link2">
 <visual>
  <origin xyz="0.300 0 0" rpy="0 0 0" />
   <geometry>
     <mesh filename="package://robot_simulation/meshes/head_link_R01.stl" scale="0.001 0.001 0.001"/>  
   </geometry>
   <material name="black"/>
 </visual>
 <collision>
  <origin xyz="0.300 0 0" rpy="0 0 0" />
   <geometry>
     <mesh filename="package://robot_simulation/meshes/head_link_R01.stl" scale="0.001 0.001 0.001"/>  
   </geometry>
  </collision>
 <inertial>
      <origin xyz="0.300 0 0" rpy="0 0 0"/>
      <mass value="10.0"/>
      <inertia
	  ixx="1.0" ixy="0.0" ixz="0.0"
	  iyy="1.0" iyz="0.0"
	  izz="1.0"/>
 </inertial>
</link>

<link name="probe">
 <visual>
  <origin xyz="-0.65 0 0.43" rpy="0 0 0" />
  <geometry>
     <mesh filename="package://robot_simulation/meshes/End_link_R01.stl" scale="0.001 0.001 0.001"/>  
  </geometry>
  <material name="orange"/>
 </visual>
 <collision>
  <origin xyz="-0.65 0 0.43" rpy="0 0 0" />
  <geometry>
     <mesh filename="package://robot_simulation/meshes/End_link_R01.stl" scale="0.001 0.001 0.001"/>  
  </geometry>
 </collision>
 <inertial>
      <origin xyz="-0.65 0 0.43" rpy="0 0 0"/>
      <mass value="2.0"/>
      <inertia
	  ixx="1.0" ixy="0.0" ixz="0.0"
	  iyy="1.0" iyz="0.0"
	  izz="1.0"/>
 </inertial>
</link>

<link name="gripper">
 <visual> 
  <origin xyz="0 0 0" rpy="0 0 0"/>
  <geometry>
  <cylinder length="0.08" radius="0.04"/>
  </geometry>
  <material name="black"/>
 </visual> 
 <collision>
  <origin xyz="0 0 0" rpy="0 0 0"/>
  <geometry>
  <cylinder length="0.08" radius="0.04"/>
  </geometry>
 </collision>
 <inertial>
     <origin xyz="0 0 0" rpy="0 0 0"/>
     <mass value="0.3"/>
     <inertia
         ixx="1.0" ixy="0.0" ixz="0.0" 
	 iyy="1.0" iyz="0.0"
	 izz="1.0"/>
 </inertial>
</link>

<link name="gripper_end_effector">
 <visual> 
  <origin xyz="0 0 0" rpy="0 0 0"/>
  <geometry>
  <cylinder length="0.04" radius="0.02"/>
  </geometry>
  <material name="black"/>
 </visual>
 <collision>
  <origin xyz="0 0 0" rpy="0 0 0"/>
  <geometry>
  <cylinder length="0.001" radius="0.004"/>
  </geometry>
 </collision>
 <inertial>
     <origin xyz="0 0 0" rpy="0 0 0"/>
     <mass value="0.1"/>
     <inertia
         ixx="1.0" ixy="0.0" ixz="0.0" 
	 iyy="1.0" iyz="0.0"
	 izz="1.0"/>
 </inertial>
</link>

<!-- Joints -->

<joint name="joint1" type="revolute">
  <axis xyz="0 0 1" /> 
  <limit effort="3.0" velocity="0.01" lower="-2.792" upper="2.792"/>
  <origin xyz="0 0 0.00158925" rpy="0 0 0" />
  <parent link="base_link" />
  <child link="link1" />
</joint>

<joint name="joint2" type="revolute">
 <axis xyz="0 0 1" /> 
 <limit effort="3.0" velocity="0.01" lower="-2.443" upper="2.443"/>
 <origin xyz="-0.3 0 0" rpy="0 0 0" />
 <parent link="link1" />
 <child link="link2" />
</joint>

<joint name="joint3" type="prismatic">
 <axis xyz="0 0 1" /> 
 <limit effort="3.0" velocity="0.01" lower="0.0" upper="0.13"/>
 <origin xyz="0.3 0 0" rpy="0 0 0" />
 <parent link="link2" />
 <child link="probe" />
</joint>

<joint name ="joint4" type="fixed">
 <origin xyz="-0.65 0 0.158" rpy="0 0 0"/>
 <parent link = "probe"/>
 <child link = "gripper"/>
</joint>

<joint name ="joint5" type="fixed">
 <origin xyz="-0.008 0 -0.05" rpy="0 0 0"/>
 <parent link = "gripper"/>
 <child link = "gripper_end_effector"/>
</joint>


<!-- Transmissions -->

<transmission name="tran1">
  <type>transmission_interface/SimpleTransmission</type>
    <joint name="joint1">
      <hardwareInterface>PositionJointInterface</hardwareInterface>
    </joint>
    <actuator name="motor1">
      <hardwareInterface>PositionJointInterface</hardwareInterface>
      <mechanicalReduction>1</mechanicalReduction>
    </actuator>
</transmission>

<transmission name="tran2">
   <type>transmission_interface/SimpleTransmission</type>
    <joint name="joint2">
      <hardwareInterface>PositionJointInterface</hardwareInterface>
    </joint>
    <actuator name="motor2">
      <hardwareInterface>PositionJointInterface</hardwareInterface>
      <mechanicalReduction>1</mechanicalReduction>
    </actuator>
</transmission>

<transmission name="tran3">
   <type>transmission_interface/SimpleTransmission</type>
    <joint name="joint3">
      <hardwareInterface>PositionJointInterface</hardwareInterface>
    </joint>
    <actuator name="motor3">
      <hardwareInterface>PositionJointInterface</hardwareInterface>
      <mechanicalReduction>1</mechanicalReduction>
    </actuator>
</transmission>
</robot> 
